import os
import logging
import traceback
import requests
from urllib.parse import urljoin
from tenacity import retry, stop_after_attempt, wait_exponential, RetryError
from celery import shared_task

# ‚úÖ .env forceren laden
from dotenv import load_dotenv
load_dotenv(dotenv_path=os.path.join(os.path.dirname(__file__), "..", "..", ".env"))

# ‚úÖ Logging instellen
logging.basicConfig(level=logging.INFO, format="%(asctime)s - %(levelname)s - %(message)s")
logger = logging.getLogger(__name__)

# ‚úÖ API-config (wordt nu correct uit .env geladen)
API_BASE_URL = os.getenv("API_BASE_URL", "http://127.0.0.1:5002/api")
TIMEOUT = 10
HEADERS = {"Content-Type": "application/json"}

# ‚úÖ Log de geladen API_BASE_URL (debug)
logger.info(f"üåç API_BASE_URL geladen als: {API_BASE_URL}")

# ‚úÖ Robuuste API-call met retry & logging
@retry(stop=stop_after_attempt(3), wait=wait_exponential(multiplier=1, min=5, max=20), reraise=True)
def safe_request(url, method="POST", payload=None):
    try:
        response = requests.request(method, url, json=payload, headers=HEADERS, timeout=TIMEOUT)
        response.raise_for_status()
        logger.info(f"‚úÖ API-call succesvol: {url}")
        try:
            return response.json()
        except Exception:
            logger.warning("‚ö†Ô∏è API-call gaf geen geldige JSON terug.")
            return {"message": "Non-JSON response"}
    except requests.exceptions.RequestException as e:
        logger.error(f"‚ùå RequestException bij {url}: {e}")
        raise
    except Exception as e:
        logger.error(f"‚ö†Ô∏è Onverwachte fout bij {url}: {e}")
        raise

# ‚úÖ Celery-task: Marktdata ophalen
@shared_task(name="celery_task.market_task.fetch_market_data")
def fetch_market_data():
    logger.info("üìà Taak gestart: marktdata ophalen en opslaan...")
    try:
        url = urljoin(API_BASE_URL, "/market_data/save")  # Let op juiste route
        response = safe_request(url)
        logger.info(f"‚úÖ Marktdata opgeslagen: {response}")
    except RetryError:
        logger.error("‚ùå Alle retries mislukt voor fetch_market_data.")
        logger.error(traceback.format_exc())
    except Exception as e:
        logger.error(f"‚ùå Onverwachte fout tijdens fetch_market_data: {e}")
        logger.error(traceback.format_exc())

@shared_task(name="celery_task.market_task.save_market_data_7d")
def save_market_data_7d():
    logger.info("üìä Taak gestart: 7-daagse candles ophalen en opslaan...")
    try:
        url = urljoin(API_BASE_URL, "/market_data/7d/save")
        response = safe_request(url)
        logger.info(f"‚úÖ 7d marktdata opgeslagen: {response}")
    except RetryError:
        logger.error("‚ùå Alle retries mislukt voor save_market_data_7d.")
        logger.error(traceback.format_exc())
    except Exception as e:
        logger.error(f"‚ùå Onverwachte fout tijdens save_market_data_7d: {e}")
        logger.error(traceback.format_exc())

@shared_task(name="celery_task.market_task.save_forward_returns")
def save_forward_returns():
    logger.info("üìà Taak gestart: forward returns berekenen en opslaan...")
    try:
        url = urljoin(API_BASE_URL, "/market_data/forward/save")
        response = safe_request(url)
        logger.info(f"‚úÖ Forward returns opgeslagen: {response}")
    except RetryError:
        logger.error("‚ùå Alle retries mislukt voor save_forward_returns.")
        logger.error(traceback.format_exc())
    except Exception as e:
        logger.error(f"‚ùå Onverwachte fout tijdens save_forward_returns: {e}")
        logger.error(traceback.format_exc())
